<sdf version='1.6'>
  <model name='mockingbird'>
    <link name='mockingbird/base_link'>
      <pose frame=''>0 0 0 0 -0 0</pose>
      <inertial>
        <pose frame=''>0 0 0 0 -0 0</pose>
        <mass>1.63543</mass>
        <inertia>
          <ixx>0.0126419</ixx>
          <ixy>4.49001e-05</ixy>
          <ixz>0.000123606</ixz>
          <iyy>0.0127501</iyy>
          <iyz>-1.81831e-05</iyz>
          <izz>0.0230749</izz>
        </inertia>
      </inertial>
      <collision name='mockingbird/base_link_inertia_collision'>
        <pose frame=''>0 0 0 0 -0 0</pose>
        <geometry>
          <box>
            <size>0.22 0.22 0.13</size>
          </box>
        </geometry>
        <surface>
          <contact>
            <ode/>
          </contact>
          <friction>
            <ode/>
          </friction>
        </surface>
      </collision>
      <visual name='mockingbird/base_link_inertia_visual'>
        <pose frame=''>0 0 0 0 -0 0</pose>
        <geometry>
          <mesh>
            <scale>1 1 1</scale>
            <uri>model://rotors_description/meshes/mockingbird_core.dae</uri>
          </mesh>
        </geometry>
        <material>
          <script>
            <name>Gazebo/DarkGrey</name>
            <uri>file://media/materials/scripts/gazebo.material</uri>
          </script>
        </material>
      </visual>
      <gravity>1</gravity>
      <velocity_decay/>
      <self_collide>0</self_collide>
    </link>
    <link name='mockingbird/rotor_unit_0'>
      <pose frame=''>0.233827 0.135 0 0 -0 0.523599</pose>
      <inertial>
        <pose frame=''>0 0 0 0 -0 0</pose>
        <mass>0.097214</mass>
        <inertia>
          <ixx>0.000247269</ixx>
          <ixy>0</ixy>
          <ixz>0</ixz>
          <iyy>0.000332246</iyy>
          <iyz>0</iyz>
          <izz>0.000247859</izz>
        </inertia>
      </inertial>
      <collision name='mockingbird/rotor_unit_0_collision'>
        <pose frame=''>0 0 0 0 -0 0</pose>
        <geometry>
          <box>
            <size>0.005 0.005 0.005</size>
          </box>
        </geometry>
        <surface>
          <contact>
            <ode/>
          </contact>
          <friction>
            <ode/>
          </friction>
        </surface>
      </collision>
      <visual name='mockingbird/rotor_unit_0_visual'>
        <pose frame=''>0 0 0 0 -0 0</pose>
        <geometry>
          <mesh>
            <scale>1 1 1</scale>
            <uri>model://rotors_description/meshes/mockingbird_rotorunit.dae</uri>
          </mesh>
        </geometry>
        <material>
          <script>
            <name>Gazebo/Red</name>
            <uri>file://media/materials/scripts/gazebo.material</uri>
          </script>
        </material>
      </visual>
      <gravity>1</gravity>
      <velocity_decay/>
      <self_collide>0</self_collide>
    </link>
    <joint name='rotor_unit_0_revolutejoint' type='revolute'>
      <child>mockingbird/rotor_unit_0</child>
      <parent>mockingbird/base_link</parent>
      <axis>
        <xyz>0.866025 0.5 0</xyz>
        <limit>
          <lower>-0.3</lower>
          <upper>0.3</upper>
          <effort>1000</effort>
          <velocity>4</velocity>
        </limit>
        <dynamics>
          <spring_reference>0</spring_reference>
          <spring_stiffness>0</spring_stiffness>
        </dynamics>
        <use_parent_model_frame>1</use_parent_model_frame>
      </axis>
    </joint>
    <link name='mockingbird/rotor_0'>
      <pose frame=''>0.233827 0.135 0.038 0 -0 0.523599</pose>
      <inertial>
        <pose frame=''>0 0 0 0 -0 0</pose>
        <mass>0.004</mass>
        <inertia>
          <ixx>7.8e-07</ixx>
          <ixy>0</ixy>
          <ixz>0</ixz>
          <iyy>1.95375e-05</iyy>
          <iyz>0</iyz>
          <izz>2.02575e-05</izz>
        </inertia>
      </inertial>
      <collision name='mockingbird/rotor_0_collision'>
        <pose frame=''>0 0 0 0 -0 0</pose>
        <geometry>
          <cylinder>
            <length>0.005</length>
            <radius>0.0765</radius>
          </cylinder>
        </geometry>
        <surface>
          <contact>
            <ode/>
          </contact>
          <friction>
            <ode/>
          </friction>
        </surface>
      </collision>
      <visual name='mockingbird/rotor_0_visual'>
        <pose frame=''>0 0 0 0 -0 0</pose>
        <geometry>
          <mesh>
            <scale>0.0765 0.0765 0.0765</scale>
            <uri>model://rotors_description/meshes/propeller_ccw.dae</uri>
          </mesh>
        </geometry>
        <material>
          <script>
            <name>Gazebo/Red</name>
            <uri>file://media/materials/scripts/gazebo.material</uri>
          </script>
        </material>
      </visual>
      <gravity>1</gravity>
      <velocity_decay/>
      <self_collide>0</self_collide>
    </link>
    <joint name='mockingbird/rotor_0_joint' type='revolute'>
      <child>mockingbird/rotor_0</child>
      <parent>mockingbird/rotor_unit_0</parent>
      <axis>
        <xyz>0 0 1</xyz>
        <limit>
          <lower>-1e+16</lower>
          <upper>1e+16</upper>
        </limit>
        <dynamics>
          <spring_reference>0</spring_reference>
          <spring_stiffness>0</spring_stiffness>
        </dynamics>
        <use_parent_model_frame>1</use_parent_model_frame>
      </axis>
    </joint>
    <link name='mockingbird/rotor_unit_1'>
      <pose frame=''>0 0.27 0 0 -0 1.5708</pose>
      <inertial>
        <pose frame=''>0 0 0 0 -0 0</pose>
        <mass>0.097214</mass>
        <inertia>
          <ixx>0.000247269</ixx>
          <ixy>0</ixy>
          <ixz>0</ixz>
          <iyy>0.000332246</iyy>
          <iyz>0</iyz>
          <izz>0.000247859</izz>
        </inertia>
      </inertial>
      <collision name='mockingbird/rotor_unit_1_collision'>
        <pose frame=''>0 0 0 0 -0 0</pose>
        <geometry>
          <box>
            <size>0.005 0.005 0.005</size>
          </box>
        </geometry>
        <surface>
          <contact>
            <ode/>
          </contact>
          <friction>
            <ode/>
          </friction>
        </surface>
      </collision>
      <visual name='mockingbird/rotor_unit_1_visual'>
        <pose frame=''>0 0 0 0 -0 0</pose>
        <geometry>
          <mesh>
            <scale>1 1 1</scale>
            <uri>model://rotors_description/meshes/mockingbird_rotorunit.dae</uri>
          </mesh>
        </geometry>
        <material>
          <script>
            <name>Gazebo/Red</name>
            <uri>file://media/materials/scripts/gazebo.material</uri>
          </script>
        </material>
      </visual>
      <gravity>1</gravity>
      <velocity_decay/>
      <self_collide>0</self_collide>
    </link>
    <joint name='rotor_unit_1_revolutejoint' type='revolute'>
      <child>mockingbird/rotor_unit_1</child>
      <parent>mockingbird/base_link</parent>
      <axis>
        <xyz>0 1 0</xyz>
        <limit>
          <lower>-0.3</lower>
          <upper>0.3</upper>
          <effort>1000</effort>
          <velocity>4</velocity>
        </limit>
        <dynamics>
          <spring_reference>0</spring_reference>
          <spring_stiffness>0</spring_stiffness>
        </dynamics>
        <use_parent_model_frame>1</use_parent_model_frame>
      </axis>
    </joint>
    <link name='mockingbird/rotor_1'>
      <pose frame=''>0 0.27 0.038 0 -0 1.5708</pose>
      <inertial>
        <pose frame=''>0 0 0 0 -0 0</pose>
        <mass>0.004</mass>
        <inertia>
          <ixx>7.8e-07</ixx>
          <ixy>0</ixy>
          <ixz>0</ixz>
          <iyy>1.95375e-05</iyy>
          <iyz>0</iyz>
          <izz>2.02575e-05</izz>
        </inertia>
      </inertial>
      <collision name='mockingbird/rotor_1_collision'>
        <pose frame=''>0 0 0 0 -0 0</pose>
        <geometry>
          <cylinder>
            <length>0.005</length>
            <radius>0.0765</radius>
          </cylinder>
        </geometry>
        <surface>
          <contact>
            <ode/>
          </contact>
          <friction>
            <ode/>
          </friction>
        </surface>
      </collision>
      <visual name='mockingbird/rotor_1_visual'>
        <pose frame=''>0 0 0 0 -0 0</pose>
        <geometry>
          <mesh>
            <scale>0.0765 0.0765 0.0765</scale>
            <uri>model://rotors_description/meshes/propeller_cw.dae</uri>
          </mesh>
        </geometry>
        <material>
          <script>
            <name>Gazebo/Blue</name>
            <uri>file://media/materials/scripts/gazebo.material</uri>
          </script>
        </material>
      </visual>
      <gravity>1</gravity>
      <velocity_decay/>
      <self_collide>0</self_collide>
    </link>
    <joint name='mockingbird/rotor_1_joint' type='revolute'>
      <child>mockingbird/rotor_1</child>
      <parent>mockingbird/rotor_unit_1</parent>
      <axis>
        <xyz>0 0 1</xyz>
        <limit>
          <lower>-1e+16</lower>
          <upper>1e+16</upper>
        </limit>
        <dynamics>
          <spring_reference>0</spring_reference>
          <spring_stiffness>0</spring_stiffness>
        </dynamics>
        <use_parent_model_frame>1</use_parent_model_frame>
      </axis>
    </joint>
    <link name='mockingbird/rotor_unit_2'>
      <pose frame=''>-0.233827 0.135 0 0 -0 2.61799</pose>
      <inertial>
        <pose frame=''>0 0 0 0 -0 0</pose>
        <mass>0.097214</mass>
        <inertia>
          <ixx>0.000247269</ixx>
          <ixy>0</ixy>
          <ixz>0</ixz>
          <iyy>0.000332246</iyy>
          <iyz>0</iyz>
          <izz>0.000247859</izz>
        </inertia>
      </inertial>
      <collision name='mockingbird/rotor_unit_2_collision'>
        <pose frame=''>0 0 0 0 -0 0</pose>
        <geometry>
          <box>
            <size>0.005 0.005 0.005</size>
          </box>
        </geometry>
        <surface>
          <contact>
            <ode/>
          </contact>
          <friction>
            <ode/>
          </friction>
        </surface>
      </collision>
      <visual name='mockingbird/rotor_unit_2_visual'>
        <pose frame=''>0 0 0 0 -0 0</pose>
        <geometry>
          <mesh>
            <scale>1 1 1</scale>
            <uri>model://rotors_description/meshes/mockingbird_rotorunit.dae</uri>
          </mesh>
        </geometry>
        <material>
          <script>
            <name>Gazebo/Red</name>
            <uri>file://media/materials/scripts/gazebo.material</uri>
          </script>
        </material>
      </visual>
      <gravity>1</gravity>
      <velocity_decay/>
      <self_collide>0</self_collide>
    </link>
    <joint name='rotor_unit_2_revolutejoint' type='revolute'>
      <child>mockingbird/rotor_unit_2</child>
      <parent>mockingbird/base_link</parent>
      <axis>
        <xyz>-0.866025 0.5 0</xyz>
        <limit>
          <lower>-0.3</lower>
          <upper>0.3</upper>
          <effort>1000</effort>
          <velocity>4</velocity>
        </limit>
        <dynamics>
          <spring_reference>0</spring_reference>
          <spring_stiffness>0</spring_stiffness>
        </dynamics>
        <use_parent_model_frame>1</use_parent_model_frame>
      </axis>
    </joint>
    <link name='mockingbird/rotor_2'>
      <pose frame=''>-0.233827 0.135 0.038 0 -0 2.61799</pose>
      <inertial>
        <pose frame=''>0 0 0 0 -0 0</pose>
        <mass>0.004</mass>
        <inertia>
          <ixx>7.8e-07</ixx>
          <ixy>0</ixy>
          <ixz>0</ixz>
          <iyy>1.95375e-05</iyy>
          <iyz>0</iyz>
          <izz>2.02575e-05</izz>
        </inertia>
      </inertial>
      <collision name='mockingbird/rotor_2_collision'>
        <pose frame=''>0 0 0 0 -0 0</pose>
        <geometry>
          <cylinder>
            <length>0.005</length>
            <radius>0.0765</radius>
          </cylinder>
        </geometry>
        <surface>
          <contact>
            <ode/>
          </contact>
          <friction>
            <ode/>
          </friction>
        </surface>
      </collision>
      <visual name='mockingbird/rotor_2_visual'>
        <pose frame=''>0 0 0 0 -0 0</pose>
        <geometry>
          <mesh>
            <scale>0.0765 0.0765 0.0765</scale>
            <uri>model://rotors_description/meshes/propeller_ccw.dae</uri>
          </mesh>
        </geometry>
        <material>
          <script>
            <name>Gazebo/Blue</name>
            <uri>file://media/materials/scripts/gazebo.material</uri>
          </script>
        </material>
      </visual>
      <gravity>1</gravity>
      <velocity_decay/>
      <self_collide>0</self_collide>
    </link>
    <joint name='mockingbird/rotor_2_joint' type='revolute'>
      <child>mockingbird/rotor_2</child>
      <parent>mockingbird/rotor_unit_2</parent>
      <axis>
        <xyz>0 0 1</xyz>
        <limit>
          <lower>-1e+16</lower>
          <upper>1e+16</upper>
        </limit>
        <dynamics>
          <spring_reference>0</spring_reference>
          <spring_stiffness>0</spring_stiffness>
        </dynamics>
        <use_parent_model_frame>1</use_parent_model_frame>
      </axis>
    </joint>
    <link name='mockingbird/rotor_unit_3'>
      <pose frame=''>-0.233827 -0.135 0 0 -0 -2.61799</pose>
      <inertial>
        <pose frame=''>0 0 0 0 -0 0</pose>
        <mass>0.097214</mass>
        <inertia>
          <ixx>0.000247269</ixx>
          <ixy>0</ixy>
          <ixz>0</ixz>
          <iyy>0.000332246</iyy>
          <iyz>0</iyz>
          <izz>0.000247859</izz>
        </inertia>
      </inertial>
      <collision name='mockingbird/rotor_unit_3_collision'>
        <pose frame=''>0 0 0 0 -0 0</pose>
        <geometry>
          <box>
            <size>0.005 0.005 0.005</size>
          </box>
        </geometry>
        <surface>
          <contact>
            <ode/>
          </contact>
          <friction>
            <ode/>
          </friction>
        </surface>
      </collision>
      <visual name='mockingbird/rotor_unit_3_visual'>
        <pose frame=''>0 0 0 0 -0 0</pose>
        <geometry>
          <mesh>
            <scale>1 1 1</scale>
            <uri>model://rotors_description/meshes/mockingbird_rotorunit.dae</uri>
          </mesh>
        </geometry>
        <material>
          <script>
            <name>Gazebo/Red</name>
            <uri>file://media/materials/scripts/gazebo.material</uri>
          </script>
        </material>
      </visual>
      <gravity>1</gravity>
      <velocity_decay/>
      <self_collide>0</self_collide>
    </link>
    <joint name='rotor_unit_3_revolutejoint' type='revolute'>
      <child>mockingbird/rotor_unit_3</child>
      <parent>mockingbird/base_link</parent>
      <axis>
        <xyz>-0.866025 -0.5 0</xyz>
        <limit>
          <lower>-0.3</lower>
          <upper>0.3</upper>
          <effort>1000</effort>
          <velocity>4</velocity>
        </limit>
        <dynamics>
          <spring_reference>0</spring_reference>
          <spring_stiffness>0</spring_stiffness>
        </dynamics>
        <use_parent_model_frame>1</use_parent_model_frame>
      </axis>
    </joint>
    <link name='mockingbird/rotor_3'>
      <pose frame=''>-0.233827 -0.135 0.038 0 -0 -2.61799</pose>
      <inertial>
        <pose frame=''>0 0 0 0 -0 0</pose>
        <mass>0.004</mass>
        <inertia>
          <ixx>7.8e-07</ixx>
          <ixy>0</ixy>
          <ixz>0</ixz>
          <iyy>1.95375e-05</iyy>
          <iyz>0</iyz>
          <izz>2.02575e-05</izz>
        </inertia>
      </inertial>
      <collision name='mockingbird/rotor_3_collision'>
        <pose frame=''>0 0 0 0 -0 0</pose>
        <geometry>
          <cylinder>
            <length>0.005</length>
            <radius>0.0765</radius>
          </cylinder>
        </geometry>
        <surface>
          <contact>
            <ode/>
          </contact>
          <friction>
            <ode/>
          </friction>
        </surface>
      </collision>
      <visual name='mockingbird/rotor_3_visual'>
        <pose frame=''>0 0 0 0 -0 0</pose>
        <geometry>
          <mesh>
            <scale>0.0765 0.0765 0.0765</scale>
            <uri>model://rotors_description/meshes/propeller_cw.dae</uri>
          </mesh>
        </geometry>
        <material>
          <script>
            <name>Gazebo/Blue</name>
            <uri>file://media/materials/scripts/gazebo.material</uri>
          </script>
        </material>
      </visual>
      <gravity>1</gravity>
      <velocity_decay/>
      <self_collide>0</self_collide>
    </link>
    <joint name='mockingbird/rotor_3_joint' type='revolute'>
      <child>mockingbird/rotor_3</child>
      <parent>mockingbird/rotor_unit_3</parent>
      <axis>
        <xyz>0 0 1</xyz>
        <limit>
          <lower>-1e+16</lower>
          <upper>1e+16</upper>
        </limit>
        <dynamics>
          <spring_reference>0</spring_reference>
          <spring_stiffness>0</spring_stiffness>
        </dynamics>
        <use_parent_model_frame>1</use_parent_model_frame>
      </axis>
    </joint>
    <link name='mockingbird/rotor_unit_4'>
      <pose frame=''>0 -0.27 0 0 -0 -1.5708</pose>
      <inertial>
        <pose frame=''>0 0 0 0 -0 0</pose>
        <mass>0.097214</mass>
        <inertia>
          <ixx>0.000247269</ixx>
          <ixy>0</ixy>
          <ixz>0</ixz>
          <iyy>0.000332246</iyy>
          <iyz>0</iyz>
          <izz>0.000247859</izz>
        </inertia>
      </inertial>
      <collision name='mockingbird/rotor_unit_4_collision'>
        <pose frame=''>0 0 0 0 -0 0</pose>
        <geometry>
          <box>
            <size>0.005 0.005 0.005</size>
          </box>
        </geometry>
        <surface>
          <contact>
            <ode/>
          </contact>
          <friction>
            <ode/>
          </friction>
        </surface>
      </collision>
      <visual name='mockingbird/rotor_unit_4_visual'>
        <pose frame=''>0 0 0 0 -0 0</pose>
        <geometry>
          <mesh>
            <scale>1 1 1</scale>
            <uri>model://rotors_description/meshes/mockingbird_rotorunit.dae</uri>
          </mesh>
        </geometry>
        <material>
          <script>
            <name>Gazebo/Red</name>
            <uri>file://media/materials/scripts/gazebo.material</uri>
          </script>
        </material>
      </visual>
      <gravity>1</gravity>
      <velocity_decay/>
      <self_collide>0</self_collide>
    </link>
    <joint name='rotor_unit_4_revolutejoint' type='revolute'>
      <child>mockingbird/rotor_unit_4</child>
      <parent>mockingbird/base_link</parent>
      <axis>
        <xyz>-0 -1 0</xyz>
        <limit>
          <lower>-0.3</lower>
          <upper>0.3</upper>
          <effort>1000</effort>
          <velocity>4</velocity>
        </limit>
        <dynamics>
          <spring_reference>0</spring_reference>
          <spring_stiffness>0</spring_stiffness>
        </dynamics>
        <use_parent_model_frame>1</use_parent_model_frame>
      </axis>
    </joint>
    <link name='mockingbird/rotor_4'>
      <pose frame=''>0 -0.27 0.038 0 -0 -1.5708</pose>
      <inertial>
        <pose frame=''>0 0 0 0 -0 0</pose>
        <mass>0.004</mass>
        <inertia>
          <ixx>7.8e-07</ixx>
          <ixy>0</ixy>
          <ixz>0</ixz>
          <iyy>1.95375e-05</iyy>
          <iyz>0</iyz>
          <izz>2.02575e-05</izz>
        </inertia>
      </inertial>
      <collision name='mockingbird/rotor_4_collision'>
        <pose frame=''>0 0 0 0 -0 0</pose>
        <geometry>
          <cylinder>
            <length>0.005</length>
            <radius>0.0765</radius>
          </cylinder>
        </geometry>
        <surface>
          <contact>
            <ode/>
          </contact>
          <friction>
            <ode/>
          </friction>
        </surface>
      </collision>
      <visual name='mockingbird/rotor_4_visual'>
        <pose frame=''>0 0 0 0 -0 0</pose>
        <geometry>
          <mesh>
            <scale>0.0765 0.0765 0.0765</scale>
            <uri>model://rotors_description/meshes/propeller_ccw.dae</uri>
          </mesh>
        </geometry>
        <material>
          <script>
            <name>Gazebo/Blue</name>
            <uri>file://media/materials/scripts/gazebo.material</uri>
          </script>
        </material>
      </visual>
      <gravity>1</gravity>
      <velocity_decay/>
      <self_collide>0</self_collide>
    </link>
    <joint name='mockingbird/rotor_4_joint' type='revolute'>
      <child>mockingbird/rotor_4</child>
      <parent>mockingbird/rotor_unit_4</parent>
      <axis>
        <xyz>0 0 1</xyz>
        <limit>
          <lower>-1e+16</lower>
          <upper>1e+16</upper>
        </limit>
        <dynamics>
          <spring_reference>0</spring_reference>
          <spring_stiffness>0</spring_stiffness>
        </dynamics>
        <use_parent_model_frame>1</use_parent_model_frame>
      </axis>
    </joint>
    <link name='mockingbird/rotor_unit_5'>
      <pose frame=''>0.233827 -0.135 0 0 -0 -0.523599</pose>
      <inertial>
        <pose frame=''>0 0 0 0 -0 0</pose>
        <mass>0.097214</mass>
        <inertia>
          <ixx>0.000247269</ixx>
          <ixy>0</ixy>
          <ixz>0</ixz>
          <iyy>0.000332246</iyy>
          <iyz>0</iyz>
          <izz>0.000247859</izz>
        </inertia>
      </inertial>
      <collision name='mockingbird/rotor_unit_5_collision'>
        <pose frame=''>0 0 0 0 -0 0</pose>
        <geometry>
          <box>
            <size>0.005 0.005 0.005</size>
          </box>
        </geometry>
        <surface>
          <contact>
            <ode/>
          </contact>
          <friction>
            <ode/>
          </friction>
        </surface>
      </collision>
      <visual name='mockingbird/rotor_unit_5_visual'>
        <pose frame=''>0 0 0 0 -0 0</pose>
        <geometry>
          <mesh>
            <scale>1 1 1</scale>
            <uri>model://rotors_description/meshes/mockingbird_rotorunit.dae</uri>
          </mesh>
        </geometry>
        <material>
          <script>
            <name>Gazebo/Red</name>
            <uri>file://media/materials/scripts/gazebo.material</uri>
          </script>
        </material>
      </visual>
      <gravity>1</gravity>
      <velocity_decay/>
      <self_collide>0</self_collide>
    </link>
    <joint name='rotor_unit_5_revolutejoint' type='revolute'>
      <child>mockingbird/rotor_unit_5</child>
      <parent>mockingbird/base_link</parent>
      <axis>
        <xyz>0.866025 -0.5 0</xyz>
        <limit>
          <lower>-0.3</lower>
          <upper>0.3</upper>
          <effort>1000</effort>
          <velocity>4</velocity>
        </limit>
        <dynamics>
          <spring_reference>0</spring_reference>
          <spring_stiffness>0</spring_stiffness>
        </dynamics>
        <use_parent_model_frame>1</use_parent_model_frame>
      </axis>
    </joint>
    <link name='mockingbird/rotor_5'>
      <pose frame=''>0.233827 -0.135 0.038 0 -0 -0.523599</pose>
      <inertial>
        <pose frame=''>0 0 0 0 -0 0</pose>
        <mass>0.004</mass>
        <inertia>
          <ixx>7.8e-07</ixx>
          <ixy>0</ixy>
          <ixz>0</ixz>
          <iyy>1.95375e-05</iyy>
          <iyz>0</iyz>
          <izz>2.02575e-05</izz>
        </inertia>
      </inertial>
      <collision name='mockingbird/rotor_5_collision'>
        <pose frame=''>0 0 0 0 -0 0</pose>
        <geometry>
          <cylinder>
            <length>0.005</length>
            <radius>0.0765</radius>
          </cylinder>
        </geometry>
        <surface>
          <contact>
            <ode/>
          </contact>
          <friction>
            <ode/>
          </friction>
        </surface>
      </collision>
      <visual name='mockingbird/rotor_5_visual'>
        <pose frame=''>0 0 0 0 -0 0</pose>
        <geometry>
          <mesh>
            <scale>0.0765 0.0765 0.0765</scale>
            <uri>model://rotors_description/meshes/propeller_cw.dae</uri>
          </mesh>
        </geometry>
        <material>
          <script>
            <name>Gazebo/Red</name>
            <uri>file://media/materials/scripts/gazebo.material</uri>
          </script>
        </material>
      </visual>
      <gravity>1</gravity>
      <velocity_decay/>
      <self_collide>0</self_collide>
    </link>
    <joint name='mockingbird/rotor_5_joint' type='revolute'>
      <child>mockingbird/rotor_5</child>
      <parent>mockingbird/rotor_unit_5</parent>
      <axis>
        <xyz>0 0 1</xyz>
        <limit>
          <lower>-1e+16</lower>
          <upper>1e+16</upper>
        </limit>
        <dynamics>
          <spring_reference>0</spring_reference>
          <spring_stiffness>0</spring_stiffness>
        </dynamics>
        <use_parent_model_frame>1</use_parent_model_frame>
      </axis>
    </joint>
    <plugin name='multirotor_base_plugin' filename='librotors_gazebo_multirotor_base_plugin.so'>
      <robotNamespace>mockingbird</robotNamespace>
      <linkName>mockingbird/base_link</linkName>
      <rotorVelocitySlowdownSim>10</rotorVelocitySlowdownSim>
    </plugin>
    <plugin name='mockingbird_left_motor_model' filename='librotors_gazebo_motor_model.so'>
      <robotNamespace>mockingbird</robotNamespace>
      <jointName>mockingbird/rotor_0_joint</jointName>
      <linkName>mockingbird/rotor_0</linkName>
      <turningDirection>ccw</turningDirection>
      <timeConstantUp>0.0125</timeConstantUp>
      <timeConstantDown>0.025</timeConstantDown>
      <maxRotVelocity>838</maxRotVelocity>
      <motorConstant>1.0258296e-05</motorConstant>
      <momentConstant>0.016</momentConstant>
      <commandSubTopic>gazebo/command/motor_speed</commandSubTopic>
      <motorNumber>0</motorNumber>
      <rotorDragCoefficient>8.06428e-05</rotorDragCoefficient>
      <rollingMomentCoefficient>1e-06</rollingMomentCoefficient>
      <motorSpeedPubTopic>motor_speed/0</motorSpeedPubTopic>
      <rotorVelocitySlowdownSim>10</rotorVelocitySlowdownSim>
    </plugin>
    <plugin name='mockingbird_left_motor_model' filename='librotors_gazebo_motor_model.so'>
      <robotNamespace>mockingbird</robotNamespace>
      <jointName>mockingbird/rotor_1_joint</jointName>
      <linkName>mockingbird/rotor_1</linkName>
      <turningDirection>cw</turningDirection>
      <timeConstantUp>0.0125</timeConstantUp>
      <timeConstantDown>0.025</timeConstantDown>
      <maxRotVelocity>838</maxRotVelocity>
      <motorConstant>1.0258296e-05</motorConstant>
      <momentConstant>0.016</momentConstant>
      <commandSubTopic>gazebo/command/motor_speed</commandSubTopic>
      <motorNumber>1</motorNumber>
      <rotorDragCoefficient>8.06428e-05</rotorDragCoefficient>
      <rollingMomentCoefficient>1e-06</rollingMomentCoefficient>
      <motorSpeedPubTopic>motor_speed/1</motorSpeedPubTopic>
      <rotorVelocitySlowdownSim>10</rotorVelocitySlowdownSim>
    </plugin>
    <plugin name='mockingbird_back_left_motor_model' filename='librotors_gazebo_motor_model.so'>
      <robotNamespace>mockingbird</robotNamespace>
      <jointName>mockingbird/rotor_2_joint</jointName>
      <linkName>mockingbird/rotor_2</linkName>
      <turningDirection>ccw</turningDirection>
      <timeConstantUp>0.0125</timeConstantUp>
      <timeConstantDown>0.025</timeConstantDown>
      <maxRotVelocity>838</maxRotVelocity>
      <motorConstant>1.0258296e-05</motorConstant>
      <momentConstant>0.016</momentConstant>
      <commandSubTopic>gazebo/command/motor_speed</commandSubTopic>
      <motorNumber>2</motorNumber>
      <rotorDragCoefficient>8.06428e-05</rotorDragCoefficient>
      <rollingMomentCoefficient>1e-06</rollingMomentCoefficient>
      <motorSpeedPubTopic>motor_speed/2</motorSpeedPubTopic>
      <rotorVelocitySlowdownSim>10</rotorVelocitySlowdownSim>
    </plugin>
    <plugin name='mockingbird_back_right_motor_model' filename='librotors_gazebo_motor_model.so'>
      <robotNamespace>mockingbird</robotNamespace>
      <jointName>mockingbird/rotor_3_joint</jointName>
      <linkName>mockingbird/rotor_3</linkName>
      <turningDirection>cw</turningDirection>
      <timeConstantUp>0.0125</timeConstantUp>
      <timeConstantDown>0.025</timeConstantDown>
      <maxRotVelocity>838</maxRotVelocity>
      <motorConstant>1.0258296e-05</motorConstant>
      <momentConstant>0.016</momentConstant>
      <commandSubTopic>gazebo/command/motor_speed</commandSubTopic>
      <motorNumber>3</motorNumber>
      <rotorDragCoefficient>8.06428e-05</rotorDragCoefficient>
      <rollingMomentCoefficient>1e-06</rollingMomentCoefficient>
      <motorSpeedPubTopic>motor_speed/3</motorSpeedPubTopic>
      <rotorVelocitySlowdownSim>10</rotorVelocitySlowdownSim>
    </plugin>
    <plugin name='mockingbird_right_motor_model' filename='librotors_gazebo_motor_model.so'>
      <robotNamespace>mockingbird</robotNamespace>
      <jointName>mockingbird/rotor_4_joint</jointName>
      <linkName>mockingbird/rotor_4</linkName>
      <turningDirection>ccw</turningDirection>
      <timeConstantUp>0.0125</timeConstantUp>
      <timeConstantDown>0.025</timeConstantDown>
      <maxRotVelocity>838</maxRotVelocity>
      <motorConstant>1.0258296e-05</motorConstant>
      <momentConstant>0.016</momentConstant>
      <commandSubTopic>gazebo/command/motor_speed</commandSubTopic>
      <motorNumber>4</motorNumber>
      <rotorDragCoefficient>8.06428e-05</rotorDragCoefficient>
      <rollingMomentCoefficient>1e-06</rollingMomentCoefficient>
      <motorSpeedPubTopic>motor_speed/4</motorSpeedPubTopic>
      <rotorVelocitySlowdownSim>10</rotorVelocitySlowdownSim>
    </plugin>
    <static>0</static>
    <plugin name='mockingbird_front_right_motor_model' filename='librotors_gazebo_motor_model.so'>
      <robotNamespace>mockingbird</robotNamespace>
      <jointName>mockingbird/rotor_5_joint</jointName>
      <linkName>mockingbird/rotor_5</linkName>
      <turningDirection>cw</turningDirection>
      <timeConstantUp>0.0125</timeConstantUp>
      <timeConstantDown>0.025</timeConstantDown>
      <maxRotVelocity>838</maxRotVelocity>
      <motorConstant>1.0258296e-05</motorConstant>
      <momentConstant>0.016</momentConstant>
      <commandSubTopic>gazebo/command/motor_speed</commandSubTopic>
      <motorNumber>5</motorNumber>
      <rotorDragCoefficient>8.06428e-05</rotorDragCoefficient>
      <rollingMomentCoefficient>1e-06</rollingMomentCoefficient>
      <motorSpeedPubTopic>motor_speed/5</motorSpeedPubTopic>
      <rotorVelocitySlowdownSim>10</rotorVelocitySlowdownSim>
    </plugin>
  </model>
</sdf>
