<?xml version="1.0" ?>
<!-- =================================================================================== -->
<!-- |    This document was autogenerated by xacro from mockingbird.xacro              | -->
<!-- |    EDITING THIS FILE BY HAND IS NOT RECOMMENDED                                 | -->
<!-- =================================================================================== -->
<!--
  Copyright 2015 Fadri Furrer, ASL, ETH Zurich, Switzerland
  Copyright 2015 Michael Burri, ASL, ETH Zurich, Switzerland
  Copyright 2015 Mina Kamel, ASL, ETH Zurich, Switzerland
  Copyright 2015 Janosch Nikolic, ASL, ETH Zurich, Switzerland
  Copyright 2015 Markus Achtelik, ASL, ETH Zurich, Switzerland

  Licensed under the Apache License, Version 2.0 (the "License");
  you may not use this file except in compliance with the License.
  You may obtain a copy of the License at

  http://www.apache.org/licenses/LICENSE-2.0

  Unless required by applicable law or agreed to in writing, software
  distributed under the License is distributed on an "AS IS" BASIS,
  WITHOUT WARRANTIES OR CONDITIONS OF ANY KIND, either express or implied.
  See the License for the specific language governing permissions and
  limitations under the License.
-->
<robot name="mockingbird" xmlns:xacro="http://ros.org/wiki/xacro">
  <link name="mockingbird/base_link"/>
  <joint name="mockingbird/base_joint" type="fixed">
    <origin rpy="0 0 0" xyz="0 0 0"/>
    <parent link="mockingbird/base_link"/>
    <child link="mockingbird/base_link_inertia"/>
  </joint>
  <link name="mockingbird/base_link_inertia">
    <inertial>
      <mass value="1.63543"/>
      <!-- [kg] -->
      <origin xyz="0 0 0"/>
      <inertia ixx="0.01264185265" ixy="0.000044900117" ixz="0.00012360562" iyy="0.0127500516" iyz="-0.000018183082" izz="0.02307491809"/>
    </inertial>
    <visual>
      <origin rpy="0 0 0" xyz="0 0 0"/>
      <geometry>
        <mesh filename="package://rotors_description/meshes/mockingbird_core.dae" scale="1 1 1"/>
      </geometry>
    </visual>
    <collision>
      <origin rpy="0 0 0" xyz="0 0 0"/>
      <geometry>
        <box size="0.22 0.22 0.13"/>
        <!-- [m] [m] [m] -->
      </geometry>
    </collision>
  </link>
  <gazebo reference="mockingbird/base_link">
    <material>Gazebo/DarkGrey</material>
  </gazebo>
  <!-- attach multirotor_base_plugin to the base_link -->
  <gazebo>
    <plugin filename="librotors_gazebo_multirotor_base_plugin.so" name="multirotor_base_plugin">
      <robotNamespace>mockingbird</robotNamespace>
      <linkName>mockingbird/base_link</linkName>
      <rotorVelocitySlowdownSim>10</rotorVelocitySlowdownSim>
    </plugin>
  </gazebo>
  <joint name="rotor_unit_0_revolutejoint" type="revolute">
    <origin rpy="0 0 0.52359877559" xyz="0.233826859022 0.135 0"/>
    <axis xyz="1 0 0"/>
    <limit effort="1000" lower="-0.3" upper="0.3" velocity="4"/>
    <!-- TODO(ff): not currently set because it's not yet supported -->
    <!-- <limit effort="2000" velocity="${max_rot_velocity}" /> -->
    <parent link="mockingbird/base_link"/>
    <child link="mockingbird/rotor_unit_0"/>
  </joint>
  <link name="mockingbird/rotor_unit_0">
    <inertial>
      <mass value="0.097214"/>
      <!-- [kg] -->
      <inertia ixx="0.000247268773" ixy="0" ixz="0" iyy="0.0003322455" iyz="0" izz="0.0002478588"/>
    </inertial>
    <visual>
      <geometry>
        <!-- <cylinder length="0.005" radius="${radius_rotor}"/> -->
        <!-- [m] -->
        <mesh filename="package://rotors_description/meshes/mockingbird_rotorunit.dae" scale="1 1 1"/>
      </geometry>
    </visual>
    <collision>
      <geometry>
        <box size="0.005 0.005 0.005"/>
        <!-- [m] -->
      </geometry>
    </collision>
  </link>
  <transmission name="rotor_unit_0_trans">
    <type>transmission_interface/SimpleTransmission</type>
    <joint name="rotor_unit_0_revolutejoint">
      <hardwareInterface>EffortJointInterface</hardwareInterface>
    </joint>
    <actuator name="rotor_unit_0_tiltmotor">
      <hardwareInterface>EffortJointInterface</hardwareInterface>
      <mechanicalReduction>1</mechanicalReduction>
    </actuator>
  </transmission>
  <gazebo reference="mockingbird/rotor_unit_0">
    <material>Gazebo/Red</material>
  </gazebo>
  <joint name="rotor_unit_1_revolutejoint" type="revolute">
    <origin rpy="0 0 1.57079632679" xyz="0 0.27 0"/>
    <axis xyz="1 0 0"/>
    <limit effort="1000" lower="-0.3" upper="0.3" velocity="4"/>
    <!-- TODO(ff): not currently set because it's not yet supported -->
    <!-- <limit effort="2000" velocity="${max_rot_velocity}" /> -->
    <parent link="mockingbird/base_link"/>
    <child link="mockingbird/rotor_unit_1"/>
  </joint>
  <link name="mockingbird/rotor_unit_1">
    <inertial>
      <mass value="0.097214"/>
      <!-- [kg] -->
      <inertia ixx="0.000247268773" ixy="0" ixz="0" iyy="0.0003322455" iyz="0" izz="0.0002478588"/>
    </inertial>
    <visual>
      <geometry>
        <!-- <cylinder length="0.005" radius="${radius_rotor}"/> -->
        <!-- [m] -->
        <mesh filename="package://rotors_description/meshes/mockingbird_rotorunit.dae" scale="1 1 1"/>
      </geometry>
    </visual>
    <collision>
      <geometry>
        <box size="0.005 0.005 0.005"/>
        <!-- [m] -->
      </geometry>
    </collision>
  </link>
  <transmission name="rotor_unit_1_trans">
    <type>transmission_interface/SimpleTransmission</type>
    <joint name="rotor_unit_1_revolutejoint">
      <hardwareInterface>EffortJointInterface</hardwareInterface>
    </joint>
    <actuator name="rotor_unit_1_tiltmotor">
      <hardwareInterface>EffortJointInterface</hardwareInterface>
      <mechanicalReduction>1</mechanicalReduction>
    </actuator>
  </transmission>
  <gazebo reference="mockingbird/rotor_unit_1">
    <material>Gazebo/Red</material>
  </gazebo>
  <joint name="rotor_unit_2_revolutejoint" type="revolute">
    <origin rpy="0 0 2.61799387799" xyz="-0.233826859022 0.135 0"/>
    <axis xyz="1 0 0"/>
    <limit effort="1000" lower="-0.3" upper="0.3" velocity="4"/>
    <!-- TODO(ff): not currently set because it's not yet supported -->
    <!-- <limit effort="2000" velocity="${max_rot_velocity}" /> -->
    <parent link="mockingbird/base_link"/>
    <child link="mockingbird/rotor_unit_2"/>
  </joint>
  <link name="mockingbird/rotor_unit_2">
    <inertial>
      <mass value="0.097214"/>
      <!-- [kg] -->
      <inertia ixx="0.000247268773" ixy="0" ixz="0" iyy="0.0003322455" iyz="0" izz="0.0002478588"/>
    </inertial>
    <visual>
      <geometry>
        <!-- <cylinder length="0.005" radius="${radius_rotor}"/> -->
        <!-- [m] -->
        <mesh filename="package://rotors_description/meshes/mockingbird_rotorunit.dae" scale="1 1 1"/>
      </geometry>
    </visual>
    <collision>
      <geometry>
        <box size="0.005 0.005 0.005"/>
        <!-- [m] -->
      </geometry>
    </collision>
  </link>
  <transmission name="rotor_unit_2_trans">
    <type>transmission_interface/SimpleTransmission</type>
    <joint name="rotor_unit_2_revolutejoint">
      <hardwareInterface>EffortJointInterface</hardwareInterface>
    </joint>
    <actuator name="rotor_unit_2_tiltmotor">
      <hardwareInterface>EffortJointInterface</hardwareInterface>
      <mechanicalReduction>1</mechanicalReduction>
    </actuator>
  </transmission>
  <gazebo reference="mockingbird/rotor_unit_2">
    <material>Gazebo/Red</material>
  </gazebo>
  <joint name="rotor_unit_3_revolutejoint" type="revolute">
    <origin rpy="0 0 3.66519142919" xyz="-0.233826859022 -0.135 0"/>
    <axis xyz="1 0 0"/>
    <limit effort="1000" lower="-0.3" upper="0.3" velocity="4"/>
    <!-- TODO(ff): not currently set because it's not yet supported -->
    <!-- <limit effort="2000" velocity="${max_rot_velocity}" /> -->
    <parent link="mockingbird/base_link"/>
    <child link="mockingbird/rotor_unit_3"/>
  </joint>
  <link name="mockingbird/rotor_unit_3">
    <inertial>
      <mass value="0.097214"/>
      <!-- [kg] -->
      <inertia ixx="0.000247268773" ixy="0" ixz="0" iyy="0.0003322455" iyz="0" izz="0.0002478588"/>
    </inertial>
    <visual>
      <geometry>
        <!-- <cylinder length="0.005" radius="${radius_rotor}"/> -->
        <!-- [m] -->
        <mesh filename="package://rotors_description/meshes/mockingbird_rotorunit.dae" scale="1 1 1"/>
      </geometry>
    </visual>
    <collision>
      <geometry>
        <box size="0.005 0.005 0.005"/>
        <!-- [m] -->
      </geometry>
    </collision>
  </link>
  <transmission name="rotor_unit_3_trans">
    <type>transmission_interface/SimpleTransmission</type>
    <joint name="rotor_unit_3_revolutejoint">
      <hardwareInterface>EffortJointInterface</hardwareInterface>
    </joint>
    <actuator name="rotor_unit_3_tiltmotor">
      <hardwareInterface>EffortJointInterface</hardwareInterface>
      <mechanicalReduction>1</mechanicalReduction>
    </actuator>
  </transmission>
  <gazebo reference="mockingbird/rotor_unit_3">
    <material>Gazebo/Red</material>
  </gazebo>
  <joint name="rotor_unit_4_revolutejoint" type="revolute">
    <origin rpy="0 0 4.71238898038" xyz="0 -0.27 0"/>
    <axis xyz="1 0 0"/>
    <limit effort="1000" lower="-0.3" upper="0.3" velocity="4"/>
    <!-- TODO(ff): not currently set because it's not yet supported -->
    <!-- <limit effort="2000" velocity="${max_rot_velocity}" /> -->
    <parent link="mockingbird/base_link"/>
    <child link="mockingbird/rotor_unit_4"/>
  </joint>
  <link name="mockingbird/rotor_unit_4">
    <inertial>
      <mass value="0.097214"/>
      <!-- [kg] -->
      <inertia ixx="0.000247268773" ixy="0" ixz="0" iyy="0.0003322455" iyz="0" izz="0.0002478588"/>
    </inertial>
    <visual>
      <geometry>
        <!-- <cylinder length="0.005" radius="${radius_rotor}"/> -->
        <!-- [m] -->
        <mesh filename="package://rotors_description/meshes/mockingbird_rotorunit.dae" scale="1 1 1"/>
      </geometry>
    </visual>
    <collision>
      <geometry>
        <box size="0.005 0.005 0.005"/>
        <!-- [m] -->
      </geometry>
    </collision>
  </link>
  <transmission name="rotor_unit_4_trans">
    <type>transmission_interface/SimpleTransmission</type>
    <joint name="rotor_unit_4_revolutejoint">
      <hardwareInterface>EffortJointInterface</hardwareInterface>
    </joint>
    <actuator name="rotor_unit_4_tiltmotor">
      <hardwareInterface>EffortJointInterface</hardwareInterface>
      <mechanicalReduction>1</mechanicalReduction>
    </actuator>
  </transmission>
  <gazebo reference="mockingbird/rotor_unit_4">
    <material>Gazebo/Red</material>
  </gazebo>
  <joint name="rotor_unit_5_revolutejoint" type="revolute">
    <origin rpy="0 0 5.75958653158" xyz="0.233826859022 -0.135 0"/>
    <axis xyz="1 0 0"/>
    <limit effort="1000" lower="-0.3" upper="0.3" velocity="4"/>
    <!-- TODO(ff): not currently set because it's not yet supported -->
    <!-- <limit effort="2000" velocity="${max_rot_velocity}" /> -->
    <parent link="mockingbird/base_link"/>
    <child link="mockingbird/rotor_unit_5"/>
  </joint>
  <link name="mockingbird/rotor_unit_5">
    <inertial>
      <mass value="0.097214"/>
      <!-- [kg] -->
      <inertia ixx="0.000247268773" ixy="0" ixz="0" iyy="0.0003322455" iyz="0" izz="0.0002478588"/>
    </inertial>
    <visual>
      <geometry>
        <!-- <cylinder length="0.005" radius="${radius_rotor}"/> -->
        <!-- [m] -->
        <mesh filename="package://rotors_description/meshes/mockingbird_rotorunit.dae" scale="1 1 1"/>
      </geometry>
    </visual>
    <collision>
      <geometry>
        <box size="0.005 0.005 0.005"/>
        <!-- [m] -->
      </geometry>
    </collision>
  </link>
  <transmission name="rotor_unit_5_trans">
    <type>transmission_interface/SimpleTransmission</type>
    <joint name="rotor_unit_5_revolutejoint">
      <hardwareInterface>EffortJointInterface</hardwareInterface>
    </joint>
    <actuator name="rotor_unit_5_tiltmotor">
      <hardwareInterface>EffortJointInterface</hardwareInterface>
      <mechanicalReduction>1</mechanicalReduction>
    </actuator>
  </transmission>
  <gazebo reference="mockingbird/rotor_unit_5">
    <material>Gazebo/Red</material>
  </gazebo>
  <joint name="mockingbird/rotor_0_joint" type="continuous">
    <origin rpy="0 0 0" xyz="0 0 0.038"/>
    <axis xyz="0 0 1"/>
    <!-- TODO(ff): not currently set because it's not yet supported -->
    <!-- <limit effort="2000" velocity="${max_rot_velocity}" /> -->
    <parent link="mockingbird/rotor_unit_0"/>
    <child link="mockingbird/rotor_0"/>
  </joint>
  <link name="mockingbird/rotor_0">
    <inertial>
      <mass value="0.004"/>
      <!-- [kg] -->
      <inertia ixx="7.79999688e-07" ixy="0.0" ixz="0.0" iyy="1.9537492185e-05" iyz="0.0" izz="2.0257491897e-05"/>
    </inertial>
    <visual>
      <geometry>
        <mesh filename="package://rotors_description/meshes/propeller_ccw.dae" scale="0.0765 0.0765 0.0765"/>
        <!-- The propeller meshes have a radius of 1m -->
        <!-- <box size="${2*radius_rotor} 0.01 0.005"/> -->
      </geometry>
    </visual>
    <collision>
      <geometry>
        <cylinder length="0.005" radius="0.0765"/>
        <!-- [m] -->
      </geometry>
    </collision>
  </link>
  <gazebo>
    <plugin filename="librotors_gazebo_motor_model.so" name="mockingbird_left_motor_model">
      <robotNamespace>mockingbird</robotNamespace>
      <jointName>mockingbird/rotor_0_joint</jointName>
      <linkName>mockingbird/rotor_0</linkName>
      <turningDirection>ccw</turningDirection>
      <timeConstantUp>0.0125</timeConstantUp>
      <timeConstantDown>0.025</timeConstantDown>
      <maxRotVelocity>838</maxRotVelocity>
      <motorConstant>1.0258296e-05</motorConstant>
      <momentConstant>0.016</momentConstant>
      <commandSubTopic>gazebo/command/motor_speed</commandSubTopic>
      <motorNumber>0</motorNumber>
      <rotorDragCoefficient>8.06428e-05</rotorDragCoefficient>
      <rollingMomentCoefficient>1e-06</rollingMomentCoefficient>
      <motorSpeedPubTopic>motor_speed/0</motorSpeedPubTopic>
      <rotorVelocitySlowdownSim>10</rotorVelocitySlowdownSim>
    </plugin>
  </gazebo>
  <gazebo reference="mockingbird/rotor_0">
    <material>Gazebo/Red</material>
  </gazebo>
  <joint name="mockingbird/rotor_1_joint" type="continuous">
    <origin rpy="0 0 0" xyz="0 0 0.038"/>
    <axis xyz="0 0 1"/>
    <!-- TODO(ff): not currently set because it's not yet supported -->
    <!-- <limit effort="2000" velocity="${max_rot_velocity}" /> -->
    <parent link="mockingbird/rotor_unit_1"/>
    <child link="mockingbird/rotor_1"/>
  </joint>
  <link name="mockingbird/rotor_1">
    <inertial>
      <mass value="0.004"/>
      <!-- [kg] -->
      <inertia ixx="7.79999688e-07" ixy="0.0" ixz="0.0" iyy="1.9537492185e-05" iyz="0.0" izz="2.0257491897e-05"/>
    </inertial>
    <visual>
      <geometry>
        <mesh filename="package://rotors_description/meshes/propeller_cw.dae" scale="0.0765 0.0765 0.0765"/>
        <!-- The propeller meshes have a radius of 1m -->
        <!-- <box size="${2*radius_rotor} 0.01 0.005"/> -->
      </geometry>
    </visual>
    <collision>
      <geometry>
        <cylinder length="0.005" radius="0.0765"/>
        <!-- [m] -->
      </geometry>
    </collision>
  </link>
  <gazebo>
    <plugin filename="librotors_gazebo_motor_model.so" name="mockingbird_left_motor_model">
      <robotNamespace>mockingbird</robotNamespace>
      <jointName>mockingbird/rotor_1_joint</jointName>
      <linkName>mockingbird/rotor_1</linkName>
      <turningDirection>cw</turningDirection>
      <timeConstantUp>0.0125</timeConstantUp>
      <timeConstantDown>0.025</timeConstantDown>
      <maxRotVelocity>838</maxRotVelocity>
      <motorConstant>1.0258296e-05</motorConstant>
      <momentConstant>0.016</momentConstant>
      <commandSubTopic>gazebo/command/motor_speed</commandSubTopic>
      <motorNumber>1</motorNumber>
      <rotorDragCoefficient>8.06428e-05</rotorDragCoefficient>
      <rollingMomentCoefficient>1e-06</rollingMomentCoefficient>
      <motorSpeedPubTopic>motor_speed/1</motorSpeedPubTopic>
      <rotorVelocitySlowdownSim>10</rotorVelocitySlowdownSim>
    </plugin>
  </gazebo>
  <gazebo reference="mockingbird/rotor_1">
    <material>Gazebo/Blue</material>
  </gazebo>
  <joint name="mockingbird/rotor_2_joint" type="continuous">
    <origin rpy="0 0 0" xyz="0 0 0.038"/>
    <axis xyz="0 0 1"/>
    <!-- TODO(ff): not currently set because it's not yet supported -->
    <!-- <limit effort="2000" velocity="${max_rot_velocity}" /> -->
    <parent link="mockingbird/rotor_unit_2"/>
    <child link="mockingbird/rotor_2"/>
  </joint>
  <link name="mockingbird/rotor_2">
    <inertial>
      <mass value="0.004"/>
      <!-- [kg] -->
      <inertia ixx="7.79999688e-07" ixy="0.0" ixz="0.0" iyy="1.9537492185e-05" iyz="0.0" izz="2.0257491897e-05"/>
    </inertial>
    <visual>
      <geometry>
        <mesh filename="package://rotors_description/meshes/propeller_ccw.dae" scale="0.0765 0.0765 0.0765"/>
        <!-- The propeller meshes have a radius of 1m -->
        <!-- <box size="${2*radius_rotor} 0.01 0.005"/> -->
      </geometry>
    </visual>
    <collision>
      <geometry>
        <cylinder length="0.005" radius="0.0765"/>
        <!-- [m] -->
      </geometry>
    </collision>
  </link>
  <gazebo>
    <plugin filename="librotors_gazebo_motor_model.so" name="mockingbird_back_left_motor_model">
      <robotNamespace>mockingbird</robotNamespace>
      <jointName>mockingbird/rotor_2_joint</jointName>
      <linkName>mockingbird/rotor_2</linkName>
      <turningDirection>ccw</turningDirection>
      <timeConstantUp>0.0125</timeConstantUp>
      <timeConstantDown>0.025</timeConstantDown>
      <maxRotVelocity>838</maxRotVelocity>
      <motorConstant>1.0258296e-05</motorConstant>
      <momentConstant>0.016</momentConstant>
      <commandSubTopic>gazebo/command/motor_speed</commandSubTopic>
      <motorNumber>2</motorNumber>
      <rotorDragCoefficient>8.06428e-05</rotorDragCoefficient>
      <rollingMomentCoefficient>1e-06</rollingMomentCoefficient>
      <motorSpeedPubTopic>motor_speed/2</motorSpeedPubTopic>
      <rotorVelocitySlowdownSim>10</rotorVelocitySlowdownSim>
    </plugin>
  </gazebo>
  <gazebo reference="mockingbird/rotor_2">
    <material>Gazebo/Blue</material>
  </gazebo>
  <joint name="mockingbird/rotor_3_joint" type="continuous">
    <origin rpy="0 0 0" xyz="0 0 0.038"/>
    <axis xyz="0 0 1"/>
    <!-- TODO(ff): not currently set because it's not yet supported -->
    <!-- <limit effort="2000" velocity="${max_rot_velocity}" /> -->
    <parent link="mockingbird/rotor_unit_3"/>
    <child link="mockingbird/rotor_3"/>
  </joint>
  <link name="mockingbird/rotor_3">
    <inertial>
      <mass value="0.004"/>
      <!-- [kg] -->
      <inertia ixx="7.79999688e-07" ixy="0.0" ixz="0.0" iyy="1.9537492185e-05" iyz="0.0" izz="2.0257491897e-05"/>
    </inertial>
    <visual>
      <geometry>
        <mesh filename="package://rotors_description/meshes/propeller_cw.dae" scale="0.0765 0.0765 0.0765"/>
        <!-- The propeller meshes have a radius of 1m -->
        <!-- <box size="${2*radius_rotor} 0.01 0.005"/> -->
      </geometry>
    </visual>
    <collision>
      <geometry>
        <cylinder length="0.005" radius="0.0765"/>
        <!-- [m] -->
      </geometry>
    </collision>
  </link>
  <gazebo>
    <plugin filename="librotors_gazebo_motor_model.so" name="mockingbird_back_right_motor_model">
      <robotNamespace>mockingbird</robotNamespace>
      <jointName>mockingbird/rotor_3_joint</jointName>
      <linkName>mockingbird/rotor_3</linkName>
      <turningDirection>cw</turningDirection>
      <timeConstantUp>0.0125</timeConstantUp>
      <timeConstantDown>0.025</timeConstantDown>
      <maxRotVelocity>838</maxRotVelocity>
      <motorConstant>1.0258296e-05</motorConstant>
      <momentConstant>0.016</momentConstant>
      <commandSubTopic>gazebo/command/motor_speed</commandSubTopic>
      <motorNumber>3</motorNumber>
      <rotorDragCoefficient>8.06428e-05</rotorDragCoefficient>
      <rollingMomentCoefficient>1e-06</rollingMomentCoefficient>
      <motorSpeedPubTopic>motor_speed/3</motorSpeedPubTopic>
      <rotorVelocitySlowdownSim>10</rotorVelocitySlowdownSim>
    </plugin>
  </gazebo>
  <gazebo reference="mockingbird/rotor_3">
    <material>Gazebo/Blue</material>
  </gazebo>
  <joint name="mockingbird/rotor_4_joint" type="continuous">
    <origin rpy="0 0 0" xyz="0 0 0.038"/>
    <axis xyz="0 0 1"/>
    <!-- TODO(ff): not currently set because it's not yet supported -->
    <!-- <limit effort="2000" velocity="${max_rot_velocity}" /> -->
    <parent link="mockingbird/rotor_unit_4"/>
    <child link="mockingbird/rotor_4"/>
  </joint>
  <link name="mockingbird/rotor_4">
    <inertial>
      <mass value="0.004"/>
      <!-- [kg] -->
      <inertia ixx="7.79999688e-07" ixy="0.0" ixz="0.0" iyy="1.9537492185e-05" iyz="0.0" izz="2.0257491897e-05"/>
    </inertial>
    <visual>
      <geometry>
        <mesh filename="package://rotors_description/meshes/propeller_ccw.dae" scale="0.0765 0.0765 0.0765"/>
        <!-- The propeller meshes have a radius of 1m -->
        <!-- <box size="${2*radius_rotor} 0.01 0.005"/> -->
      </geometry>
    </visual>
    <collision>
      <geometry>
        <cylinder length="0.005" radius="0.0765"/>
        <!-- [m] -->
      </geometry>
    </collision>
  </link>
  <gazebo>
    <plugin filename="librotors_gazebo_motor_model.so" name="mockingbird_right_motor_model">
      <robotNamespace>mockingbird</robotNamespace>
      <jointName>mockingbird/rotor_4_joint</jointName>
      <linkName>mockingbird/rotor_4</linkName>
      <turningDirection>ccw</turningDirection>
      <timeConstantUp>0.0125</timeConstantUp>
      <timeConstantDown>0.025</timeConstantDown>
      <maxRotVelocity>838</maxRotVelocity>
      <motorConstant>1.0258296e-05</motorConstant>
      <momentConstant>0.016</momentConstant>
      <commandSubTopic>gazebo/command/motor_speed</commandSubTopic>
      <motorNumber>4</motorNumber>
      <rotorDragCoefficient>8.06428e-05</rotorDragCoefficient>
      <rollingMomentCoefficient>1e-06</rollingMomentCoefficient>
      <motorSpeedPubTopic>motor_speed/4</motorSpeedPubTopic>
      <rotorVelocitySlowdownSim>10</rotorVelocitySlowdownSim>
    </plugin>
  </gazebo>
  <gazebo reference="mockingbird/rotor_4">
    <material>Gazebo/Blue</material>
  </gazebo>
  <joint name="mockingbird/rotor_5_joint" type="continuous">
    <origin rpy="0 0 0" xyz="0 0 0.038"/>
    <axis xyz="0 0 1"/>
    <!-- TODO(ff): not currently set because it's not yet supported -->
    <!-- <limit effort="2000" velocity="${max_rot_velocity}" /> -->
    <parent link="mockingbird/rotor_unit_5"/>
    <child link="mockingbird/rotor_5"/>
  </joint>
  <link name="mockingbird/rotor_5">
    <inertial>
      <mass value="0.004"/>
      <!-- [kg] -->
      <inertia ixx="7.79999688e-07" ixy="0.0" ixz="0.0" iyy="1.9537492185e-05" iyz="0.0" izz="2.0257491897e-05"/>
    </inertial>
    <visual>
      <geometry>
        <mesh filename="package://rotors_description/meshes/propeller_cw.dae" scale="0.0765 0.0765 0.0765"/>
        <!-- The propeller meshes have a radius of 1m -->
        <!-- <box size="${2*radius_rotor} 0.01 0.005"/> -->
      </geometry>
    </visual>
    <collision>
      <geometry>
        <cylinder length="0.005" radius="0.0765"/>
        <!-- [m] -->
      </geometry>
    </collision>
  </link>
  <gazebo>
    <plugin filename="librotors_gazebo_motor_model.so" name="mockingbird_front_right_motor_model">
      <robotNamespace>mockingbird</robotNamespace>
      <jointName>mockingbird/rotor_5_joint</jointName>
      <linkName>mockingbird/rotor_5</linkName>
      <turningDirection>cw</turningDirection>
      <timeConstantUp>0.0125</timeConstantUp>
      <timeConstantDown>0.025</timeConstantDown>
      <maxRotVelocity>838</maxRotVelocity>
      <motorConstant>1.0258296e-05</motorConstant>
      <momentConstant>0.016</momentConstant>
      <commandSubTopic>gazebo/command/motor_speed</commandSubTopic>
      <motorNumber>5</motorNumber>
      <rotorDragCoefficient>8.06428e-05</rotorDragCoefficient>
      <rollingMomentCoefficient>1e-06</rollingMomentCoefficient>
      <motorSpeedPubTopic>motor_speed/5</motorSpeedPubTopic>
      <rotorVelocitySlowdownSim>10</rotorVelocitySlowdownSim>
    </plugin>
  </gazebo>
  <gazebo reference="mockingbird/rotor_5">
    <material>Gazebo/Red</material>
  </gazebo>
</robot>

