<sdf version='1.6'>
    <model name='voliro'>
        <pose>0 0 0.26 0 0 0</pose>
        <link name='base_link'>
            <pose frame=''>0 0 0 0 -0 0</pose>
            <inertial>
                <pose frame=''>0 0 0 0 -0 0</pose>
                <mass>1.71</mass>
                <!-- change weight to 1.71 instead of 2.16 -->
                <inertia>
                    <ixx>0.024203</ixx>
                    <ixy>4.50012e-05</ixy>
                    <ixz>0.000180606</ixz>
                    <iyy>0.02484</iyy>
                    <iyz>-1.81831e-05</iyz>
                    <izz>0.045521</izz>
                </inertia>
            </inertial>
            <collision name='base_link_inertia_collision'>
                <pose frame=''>0 0 0 0 -0 0</pose>
                <geometry>
                    <box>
                        <size>0.22 0.22 0.13</size>
                    </box>
                </geometry>
                <surface>
                    <contact>
                        <ode>
                            <min_depth>0.001</min_depth>
                            <max_vel>0</max_vel>
                        </ode>
                    </contact>
                    <friction>
                        <ode/>
                    </friction>
                </surface>
            </collision>
            <visual name='base_link_inertia_visual'>
                <pose frame=''>0 0 0 0 -0 0</pose>
                <geometry>
                    <mesh>
                        <scale>1 1 1</scale>
                        <uri>model://rotors_description/meshes/voliro_core.dae</uri>
                    </mesh>
                </geometry>
                <material>
                    <script>
                        <name>Gazebo/ZincYellow</name>
                        <uri>file://media/materials/scripts/gazebo.material</uri>
                    </script>
                </material>
            </visual>
            <gravity>1</gravity>
            <velocity_decay/>
            <self_collide>0</self_collide>
        </link>
        <link name='/imu_link'>
            <pose frame=''>0 0 0 0 -0 0</pose>
            <inertial>
                <pose frame=''>0 0 0 0 -0 0</pose>
                <mass>0.015</mass>
                <inertia>
                    <ixx>1e-05</ixx>
                    <ixy>0</ixy>
                    <ixz>0</ixz>
                    <iyy>1e-05</iyy>
                    <iyz>0</iyz>
                    <izz>1e-05</izz>
                </inertia>
            </inertial>
        </link>
        <joint name='/imu_joint' type='revolute'>
            <child>/imu_link</child>
            <parent>base_link</parent>
            <axis>
                <xyz>1 0 0</xyz>
                <limit>
                    <lower>0</lower>
                    <upper>0</upper>
                    <effort>0</effort>
                    <velocity>0</velocity>
                </limit>
                <dynamics>
                    <spring_reference>0</spring_reference>
                    <spring_stiffness>0</spring_stiffness>
                </dynamics>
                <use_parent_model_frame>1</use_parent_model_frame>
            </axis>
        </joint>
        <link name='rotor_unit_0'>
            <pose frame=''>0.32476 0.1875 0 0 -0 0.523599</pose>
            <inertial>
                <pose frame=''>0 0 0 0 -0 0</pose>
                <mass>0.112</mass>
                <inertia>
                    <ixx>8.4e-05</ixx>
                    <ixy>0</ixy>
                    <ixz>0</ixz>
                    <iyy>8.4e-05</iyy>
                    <iyz>0</iyz>
                    <izz>1.5e-05</izz>
                </inertia>
            </inertial>
            <collision name='rotor_unit_0_collision'>
            <pose frame=''>0 0 0.055 0 -0 0</pose>
            <geometry>
                <polyline>
                    <point>0.154 0 </point>
                    <point>0.077 -0.133 </point>
                    <point>-0.077 -0.133 </point>
                    <point>-0.154 0 </point>
                    <point>-0.077 0.133 </point>
                    <point>0.077 0.133 </point>
                    <height>0.025 </height>
                </polyline>
            </geometry>
                <surface>
                    <contact>
                        <ode/>
                    </contact>
                    <friction>
                        <ode/>
                    </friction>
                </surface>
            </collision>
            <visual name='rotor_unit_0_visual'>
                <pose frame=''>0 0 0 0 -0 0</pose>
                <geometry>
                    <mesh>
                        <scale>1 1 1</scale>
                        <uri>model://rotors_description/meshes/voliro_rotorunit.dae</uri>
                    </mesh>
                </geometry>
                <material>
                    <script>
                        <name>Gazebo/Orange</name>
                        <uri>file://media/materials/scripts/gazebo.material</uri>
                    </script>
                </material>
            </visual>
            <gravity>1</gravity>
            <velocity_decay/>
            <self_collide>0</self_collide>
        </link>
        <joint name='rotor_unit_0_revolutejoint' type='revolute'>
            <child>rotor_unit_0</child>
            <parent>base_link</parent>
            <axis>
                <xyz>0.866025 0.5 0</xyz>
                <limit>
                    <lower>-6.283</lower>
                    <upper>6.283</upper>
                    <effort>0.6</effort>
                    <velocity>6</velocity>
                </limit>
                <dynamics>
                    <spring_reference>0</spring_reference>
                    <spring_stiffness>0</spring_stiffness>
                </dynamics>
                <use_parent_model_frame>1</use_parent_model_frame>
            </axis>
        </joint>
        <link name='rotor_0'>
            <pose frame=''>0.32476 0.1875 0.055 0 -0 0.523599</pose>
            <inertial>
                <pose frame=''>0 0 0 0 -0 0</pose>
                <mass>0.015</mass>
                <inertia>
                    <ixx>2.925e-06</ixx>
                    <ixy>0</ixy>
                    <ixz>0</ixz>
                    <iyy>0.000180112</iyy>
                    <iyz>0</iyz>
                    <izz>0.000182812</izz>
                </inertia>
            </inertial>
            <visual name='rotor_0_visual'>
                <pose frame=''>0 0 0 0 -0 0</pose>
                <geometry>
                    <mesh>
                        <scale>0.12 0.12 0.12</scale>
                        <uri>model://rotors_description/meshes/propeller_cw.dae</uri>
                    </mesh>
                </geometry>
                <material>
                    <script>
                        <name>Gazebo/Red</name>
                        <uri>file://media/materials/scripts/gazebo.material</uri>
                    </script>
                </material>
            </visual>
            <gravity>1</gravity>
            <velocity_decay/>
            <self_collide>0</self_collide>
        </link>
        <joint name='rotor_0_joint' type='revolute'>
            <child>rotor_0</child>
            <parent>rotor_unit_0</parent>
            <axis>
                <xyz>0 0 1</xyz>
                <limit>
                    <lower>-1e+16</lower>
                    <upper>1e+16</upper>
                </limit>
                <dynamics>
                    <spring_reference>0</spring_reference>
                    <spring_stiffness>0</spring_stiffness>
                </dynamics>
                <use_parent_model_frame>1</use_parent_model_frame>
            </axis>
        </joint>
        <link name='rotor_unit_1'>
            <pose frame=''>0 0.375 0 0 -0 1.5708</pose>
            <inertial>
                <pose frame=''>0 0 0 0 -0 0</pose>
                <mass>0.112</mass>
                <inertia>
                    <ixx>8.4e-05</ixx>
                    <ixy>0</ixy>
                    <ixz>0</ixz>
                    <iyy>8.4e-05</iyy>
                    <iyz>0</iyz>
                    <izz>1.5e-05</izz>
                </inertia>
            </inertial>
            <collision name='rotor_unit_1_collision'>
                <pose frame=''>0 0 0.055 0 -0 0</pose>
                <geometry>
                    <polyline>
                        <point>0.154 0 </point>
                        <point>0.077 -0.133 </point>
                        <point>-0.077 -0.133 </point>
                        <point>-0.154 0 </point>
                        <point>-0.077 0.133 </point>
                        <point>0.077 0.133 </point>
                        <height>0.025 </height>
                    </polyline>
                </geometry>
                <surface>
                    <contact>
                        <ode/>
                    </contact>
                    <friction>
                        <ode/>
                    </friction>
                </surface>
            </collision>
            <visual name='rotor_unit_1_visual'>
                <pose frame=''>0 0 0 0 -0 0</pose>
                <geometry>
                    <mesh>
                        <scale>1 1 1</scale>
                        <uri>model://rotors_description/meshes/voliro_rotorunit.dae</uri>
                    </mesh>
                </geometry>
                <material>
                    <script>
                        <name>Gazebo/beige</name>
                        <uri>file://media/materials/scripts/gazebo.material</uri>
                    </script>
                </material>
            </visual>
            <gravity>1</gravity>
            <velocity_decay/>
            <self_collide>0</self_collide>
        </link>
        <joint name='rotor_unit_1_revolutejoint' type='revolute'>
            <child>rotor_unit_1</child>
            <parent>base_link</parent>
            <axis>
                <xyz>0 1 0</xyz>
                <limit>
                    <lower>-6.283</lower>
                    <upper>6.283</upper>
                    <effort>0.6</effort>
                    <velocity>6</velocity>
                </limit>
                <dynamics>
                    <spring_reference>0</spring_reference>
                    <spring_stiffness>0</spring_stiffness>
                </dynamics>
                <use_parent_model_frame>1</use_parent_model_frame>
            </axis>
        </joint>
        <link name='rotor_1'>
            <pose frame=''>0 0.375 0.055 0 -0 1.5708</pose>
            <inertial>
                <pose frame=''>0 0 0 0 -0 0</pose>
                <mass>0.015</mass>
                <inertia>
                    <ixx>2.925e-06</ixx>
                    <ixy>0</ixy>
                    <ixz>0</ixz>
                    <iyy>0.000180112</iyy>
                    <iyz>0</iyz>
                    <izz>0.000182812</izz>
                </inertia>
            </inertial>
            <visual name='rotor_1_visual'>
                <pose frame=''>0 0 0 0 -0 0</pose>
                <geometry>
                    <mesh>
                        <scale>0.12 0.12 0.12</scale>
                        <uri>model://rotors_description/meshes/propeller_ccw.dae</uri>
                    </mesh>
                </geometry>
                <material>
                    <script>
                        <name>Gazebo/Blue</name>
                        <uri>file://media/materials/scripts/gazebo.material</uri>
                    </script>
                </material>
            </visual>
            <gravity>1</gravity>
            <velocity_decay/>
            <self_collide>0</self_collide>
        </link>
        <joint name='rotor_1_joint' type='revolute'>
            <child>rotor_1</child>
            <parent>rotor_unit_1</parent>
            <axis>
                <xyz>0 0 1</xyz>
                <limit>
                    <lower>-1e+16</lower>
                    <upper>1e+16</upper>
                </limit>
                <dynamics>
                    <spring_reference>0</spring_reference>
                    <spring_stiffness>0</spring_stiffness>
                </dynamics>
                <use_parent_model_frame>1</use_parent_model_frame>
            </axis>
        </joint>
        <link name='rotor_unit_2'>
            <pose frame=''>-0.32476 0.1875 0 0 -0 2.61799</pose>
            <inertial>
                <pose frame=''>0 0 0 0 -0 0</pose>
                <mass>0.112</mass>
                <inertia>
                    <ixx>8.4e-05</ixx>
                    <ixy>0</ixy>
                    <ixz>0</ixz>
                    <iyy>8.4e-05</iyy>
                    <iyz>0</iyz>
                    <izz>1.5e-05</izz>
                </inertia>
            </inertial>
            <collision name='rotor_unit_2_collision'>
                <pose frame=''>0 0 0.055 0 -0 0</pose>
                <geometry>
                    <polyline>
                        <point>0.154 0 </point>
                        <point>0.077 -0.133 </point>
                        <point>-0.077 -0.133 </point>
                        <point>-0.154 0 </point>
                        <point>-0.077 0.133 </point>
                        <point>0.077 0.133 </point>
                        <height>0.025 </height>
                    </polyline>
                </geometry>
                <surface>
                    <contact>
                        <ode/>
                    </contact>
                    <friction>
                        <ode/>
                    </friction>
                </surface>
            </collision>
            <visual name='rotor_unit_2_visual'>
                <pose frame=''>0 0 0 0 -0 0</pose>
                <geometry>
                    <mesh>
                        <scale>1 1 1</scale>
                        <uri>model://rotors_description/meshes/voliro_rotorunit.dae</uri>
                    </mesh>
                </geometry>
                <material>
                    <script>
                        <name>Gazebo/beige</name>
                        <uri>file://media/materials/scripts/gazebo.material</uri>
                    </script>
                </material>
            </visual>
            <gravity>1</gravity>
            <velocity_decay/>
            <self_collide>0</self_collide>
        </link>
        <joint name='rotor_unit_2_revolutejoint' type='revolute'>
            <child>rotor_unit_2</child>
            <parent>base_link</parent>
            <axis>
                <xyz>-0.866025 0.5 0</xyz>
                <limit>
                    <lower>-6.283</lower>
                    <upper>6.283</upper>
                    <effort>0.6</effort>
                    <velocity>6</velocity>
                </limit>
                <dynamics>
                    <spring_reference>0</spring_reference>
                    <spring_stiffness>0</spring_stiffness>
                </dynamics>
                <use_parent_model_frame>1</use_parent_model_frame>
            </axis>
        </joint>
        <link name='rotor_2'>
            <pose frame=''>-0.32476 0.1875 0.055 0 -0 2.61799</pose>
            <inertial>
                <pose frame=''>0 0 0 0 -0 0</pose>
                <mass>0.015</mass>
                <inertia>
                    <ixx>2.925e-06</ixx>
                    <ixy>0</ixy>
                    <ixz>0</ixz>
                    <iyy>0.000180112</iyy>
                    <iyz>0</iyz>
                    <izz>0.000182812</izz>
                </inertia>
            </inertial>
            <visual name='rotor_2_visual'>
                <pose frame=''>0 0 0 0 -0 0</pose>
                <geometry>
                    <mesh>
                        <scale>0.12 0.12 0.12</scale>
                        <uri>model://rotors_description/meshes/propeller_cw.dae</uri>
                    </mesh>
                </geometry>
                <material>
                    <script>
                        <name>Gazebo/Red</name>
                        <uri>file://media/materials/scripts/gazebo.material</uri>
                    </script>
                </material>
            </visual>
            <gravity>1</gravity>
            <velocity_decay/>
            <self_collide>0</self_collide>
        </link>
        <joint name='rotor_2_joint' type='revolute'>
            <child>rotor_2</child>
            <parent>rotor_unit_2</parent>
            <axis>
                <xyz>0 0 1</xyz>
                <limit>
                    <lower>-1e+16</lower>
                    <upper>1e+16</upper>
                </limit>
                <dynamics>
                    <spring_reference>0</spring_reference>
                    <spring_stiffness>0</spring_stiffness>
                </dynamics>
                <use_parent_model_frame>1</use_parent_model_frame>
            </axis>
        </joint>
        <link name='rotor_unit_3'>
            <pose frame=''>-0.32476 -0.1875 0 0 -0 -2.61799</pose>
            <inertial>
                <pose frame=''>0 0 0 0 -0 0</pose>
                <mass>0.112</mass>
                <inertia>
                    <ixx>8.4e-05</ixx>
                    <ixy>0</ixy>
                    <ixz>0</ixz>
                    <iyy>8.4e-05</iyy>
                    <iyz>0</iyz>
                    <izz>1.5e-05</izz>
                </inertia>
            </inertial>
            <collision name='rotor_unit_3_collision'>
                <pose frame=''>0 0 0.055 0 -0 0</pose>
                <geometry>
                    <polyline>
                        <point>0.154 0 </point>
                        <point>0.077 -0.133 </point>
                        <point>-0.077 -0.133 </point>
                        <point>-0.154 0 </point>
                        <point>-0.077 0.133 </point>
                        <point>0.077 0.133 </point>
                        <height>0.025 </height>
                    </polyline>
                </geometry>
                <surface>
                    <contact>
                        <ode/>
                    </contact>
                    <friction>
                        <ode/>
                    </friction>
                </surface>
            </collision>
            <visual name='rotor_unit_3_visual'>
                <pose frame=''>0 0 0 0 -0 0</pose>
                <geometry>
                    <mesh>
                        <scale>1 1 1</scale>
                        <uri>model://rotors_description/meshes/voliro_rotorunit.dae</uri>
                    </mesh>
                </geometry>
                <material>
                    <script>
                        <name>Gazebo/beige</name>
                        <uri>file://media/materials/scripts/gazebo.material</uri>
                    </script>
                </material>
            </visual>
            <gravity>1</gravity>
            <velocity_decay/>
            <self_collide>0</self_collide>
        </link>
        <joint name='rotor_unit_3_revolutejoint' type='revolute'>
            <child>rotor_unit_3</child>
            <parent>base_link</parent>
            <axis>
                <xyz>-0.866025 -0.5 0</xyz>
                <limit>
                    <lower>-6.283</lower>
                    <upper>6.283</upper>
                    <effort>0.6</effort>
                    <velocity>6</velocity>
                </limit>
                <dynamics>
                    <spring_reference>0</spring_reference>
                    <spring_stiffness>0</spring_stiffness>
                </dynamics>
                <use_parent_model_frame>1</use_parent_model_frame>
            </axis>
        </joint>
        <link name='rotor_3'>
            <pose frame=''>-0.32476 -0.1875 0.055 0 -0 -2.61799</pose>
            <inertial>
                <pose frame=''>0 0 0 0 -0 0</pose>
                <mass>0.015</mass>
                <inertia>
                    <ixx>2.925e-06</ixx>
                    <ixy>0</ixy>
                    <ixz>0</ixz>
                    <iyy>0.000180112</iyy>
                    <iyz>0</iyz>
                    <izz>0.000182812</izz>
                </inertia>
            </inertial>
            <visual name='rotor_3_visual'>
                <pose frame=''>0 0 0 0 -0 0</pose>
                <geometry>
                    <mesh>
                        <scale>0.12 0.12 0.12</scale>
                        <uri>model://rotors_description/meshes/propeller_ccw.dae</uri>
                    </mesh>
                </geometry>
                <material>
                    <script>
                        <name>Gazebo/Blue</name>
                        <uri>file://media/materials/scripts/gazebo.material</uri>
                    </script>
                </material>
            </visual>
            <gravity>1</gravity>
            <velocity_decay/>
            <self_collide>0</self_collide>
        </link>
        <joint name='rotor_3_joint' type='revolute'>
            <child>rotor_3</child>
            <parent>rotor_unit_3</parent>
            <axis>
                <xyz>0 0 1</xyz>
                <limit>
                    <lower>-1e+16</lower>
                    <upper>1e+16</upper>
                </limit>
                <dynamics>
                    <spring_reference>0</spring_reference>
                    <spring_stiffness>0</spring_stiffness>
                </dynamics>
                <use_parent_model_frame>1</use_parent_model_frame>
            </axis>
        </joint>
        <link name='rotor_unit_4'>
            <pose frame=''>0 -0.375 0 0 -0 -1.5708</pose>
            <inertial>
                <pose frame=''>0 0 0 0 -0 0</pose>
                <mass>0.112</mass>
                <inertia>
                    <ixx>8.4e-05</ixx>
                    <ixy>0</ixy>
                    <ixz>0</ixz>
                    <iyy>8.4e-05</iyy>
                    <iyz>0</iyz>
                    <izz>1.5e-05</izz>
                </inertia>
            </inertial>
            <collision name='rotor_unit_4_collision'>
                <pose frame=''>0 0 0.055 0 -0 0</pose>
                <geometry>
                    <polyline>
                        <point>0.154 0 </point>
                        <point>0.077 -0.133 </point>
                        <point>-0.077 -0.133 </point>
                        <point>-0.154 0 </point>
                        <point>-0.077 0.133 </point>
                        <point>0.077 0.133 </point>
                        <height>0.025 </height>
                    </polyline>
                </geometry>
                <surface>
                    <contact>
                        <ode/>
                    </contact>
                    <friction>
                        <ode/>
                    </friction>
                </surface>
            </collision>
            <visual name='rotor_unit_4_visual'>
                <pose frame=''>0 0 0 0 -0 0</pose>
                <geometry>
                    <mesh>
                        <scale>1 1 1</scale>
                        <uri>model://rotors_description/meshes/voliro_rotorunit.dae</uri>
                    </mesh>
                </geometry>
                <material>
                    <script>
                        <name>Gazebo/beige</name>
                        <uri>file://media/materials/scripts/gazebo.material</uri>
                    </script>
                </material>
            </visual>
            <gravity>1</gravity>
            <velocity_decay/>
            <self_collide>0</self_collide>
        </link>
        <joint name='rotor_unit_4_revolutejoint' type='revolute'>
            <child>rotor_unit_4</child>
            <parent>base_link</parent>
            <axis>
                <xyz>-0 -1 0</xyz>
                <limit>
                    <lower>-6.283</lower>
                    <upper>6.283</upper>
                    <effort>0.6</effort>
                    <velocity>6</velocity>
                </limit>
                <dynamics>
                    <spring_reference>0</spring_reference>
                    <spring_stiffness>0</spring_stiffness>
                </dynamics>
                <use_parent_model_frame>1</use_parent_model_frame>
            </axis>
        </joint>
        <link name='rotor_4'>
            <pose frame=''>0 -0.375 0.055 0 -0 -1.5708</pose>
            <inertial>
                <pose frame=''>0 0 0 0 -0 0</pose>
                <mass>0.015</mass>
                <inertia>
                    <ixx>2.925e-06</ixx>
                    <ixy>0</ixy>
                    <ixz>0</ixz>
                    <iyy>0.000180112</iyy>
                    <iyz>0</iyz>
                    <izz>0.000182812</izz>
                </inertia>
            </inertial>
            <visual name='rotor_4_visual'>
                <pose frame=''>0 0 0 0 -0 0</pose>
                <geometry>
                    <mesh>
                        <scale>0.12 0.12 0.12</scale>
                        <uri>model://rotors_description/meshes/propeller_cw.dae</uri>
                    </mesh>
                </geometry>
                <material>
                    <script>
                        <name>Gazebo/Red</name>
                        <uri>file://media/materials/scripts/gazebo.material</uri>
                    </script>
                </material>
            </visual>
            <gravity>1</gravity>
            <velocity_decay/>
            <self_collide>0</self_collide>
        </link>
        <joint name='rotor_4_joint' type='revolute'>
            <child>rotor_4</child>
            <parent>rotor_unit_4</parent>
            <axis>
                <xyz>0 0 1</xyz>
                <limit>
                    <lower>-1e+16</lower>
                    <upper>1e+16</upper>
                </limit>
                <dynamics>
                    <spring_reference>0</spring_reference>
                    <spring_stiffness>0</spring_stiffness>
                </dynamics>
                <use_parent_model_frame>1</use_parent_model_frame>
            </axis>
        </joint>
        <link name='rotor_unit_5'>
            <pose frame=''>0.32476 -0.1875 0 0 -0 -0.523599</pose>
            <inertial>
                <pose frame=''>0 0 0 0 -0 0</pose>
                <mass>0.112</mass>
                <inertia>
                    <ixx>8.4e-05</ixx>
                    <ixy>0</ixy>
                    <ixz>0</ixz>
                    <iyy>8.4e-05</iyy>
                    <iyz>0</iyz>
                    <izz>1.5e-05</izz>
                </inertia>
            </inertial>
            <collision name='rotor_unit_5_collision'>
                <pose frame=''>0 0 0.055 0 -0 0</pose>
                <geometry>
                    <polyline>
                        <point>0.154 0 </point>
                        <point>0.077 -0.133 </point>
                        <point>-0.077 -0.133 </point>
                        <point>-0.154 0 </point>
                        <point>-0.077 0.133 </point>
                        <point>0.077 0.133 </point>
                        <height>0.025 </height>
                    </polyline>
                </geometry>
                <surface>
                    <contact>
                        <ode/>
                    </contact>
                    <friction>
                        <ode/>
                    </friction>
                </surface>
            </collision>
            <visual name='rotor_unit_5_visual'>
                <pose frame=''>0 0 0 0 -0 0</pose>
                <geometry>
                    <mesh>
                        <scale>1 1 1</scale>
                        <uri>model://rotors_description/meshes/voliro_rotorunit.dae</uri>
                    </mesh>
                </geometry>
                <material>
                    <script>
                        <name>Gazebo/Orange</name>
                        <uri>file://media/materials/scripts/gazebo.material</uri>
                    </script>
                </material>
            </visual>
            <gravity>1</gravity>
            <velocity_decay/>
            <self_collide>0</self_collide>
        </link>
        <joint name='rotor_unit_5_revolutejoint' type='revolute'>
            <child>rotor_unit_5</child>
            <parent>base_link</parent>
            <axis>
                <xyz>0.866025 -0.5 0</xyz>
                <limit>
                    <lower>-6.283</lower>
                    <upper>6.283</upper>
                    <effort>0.6</effort>
                    <velocity>6</velocity>
                </limit>
                <dynamics>
                    <spring_reference>0</spring_reference>
                    <spring_stiffness>0</spring_stiffness>
                </dynamics>
                <use_parent_model_frame>1</use_parent_model_frame>
            </axis>
        </joint>
        <link name='rotor_5'>
            <pose frame=''>0.32476 -0.1875 0.055 0 -0 -0.523599</pose>
            <inertial>
                <pose frame=''>0 0 0 0 -0 0</pose>
                <mass>0.015</mass>
                <inertia>
                    <ixx>2.925e-06</ixx>
                    <ixy>0</ixy>
                    <ixz>0</ixz>
                    <iyy>0.000180112</iyy>
                    <iyz>0</iyz>
                    <izz>0.000182812</izz>
                </inertia>
            </inertial>
            <visual name='rotor_5_visual'>
                <pose frame=''>0 0 0 0 -0 0</pose>
                <geometry>
                    <mesh>
                        <scale>0.12 0.12 0.12</scale>
                        <uri>model://rotors_description/meshes/propeller_ccw.dae</uri>
                    </mesh>
                </geometry>
                <material>
                    <script>
                        <name>Gazebo/Blue</name>
                        <uri>file://media/materials/scripts/gazebo.material</uri>
                    </script>
                </material>
            </visual>
            <gravity>1</gravity>
            <velocity_decay/>
            <self_collide>0</self_collide>
        </link>
        <joint name='rotor_5_joint' type='revolute'>
            <child>rotor_5</child>
            <parent>rotor_unit_5</parent>
            <axis>
                <xyz>0 0 1</xyz>
                <limit>
                    <lower>-1e+16</lower>
                    <upper>1e+16</upper>
                </limit>
                <dynamics>
                    <spring_reference>0</spring_reference>
                    <spring_stiffness>0</spring_stiffness>
                </dynamics>
                <use_parent_model_frame>1</use_parent_model_frame>
            </axis>
        </joint>
        <plugin name='multirotor_base_plugin' filename='librotors_gazebo_multirotor_base_plugin.so'>
            <robotNamespace/>
            <linkName>base_link</linkName>
            <rotorVelocitySlowdownSim>10</rotorVelocitySlowdownSim>
        </plugin>
        <plugin name='voliro_front_left_motor_model' filename='librotors_gazebo_motor_model.so'>
            <robotNamespace/>
            <jointName>rotor_0_joint</jointName>
            <linkName>rotor_0</linkName>
            <turningDirection>cw</turningDirection>
            <timeConstantUp>0.0125</timeConstantUp>
            <timeConstantDown>0.025</timeConstantDown>
            <maxRotVelocity>838</maxRotVelocity>
            <motorConstant>1.0258296e-05</motorConstant>
            <momentConstant>0.016</momentConstant>
            <commandSubTopic>/gazebo/command/motor_speed</commandSubTopic>
            <motorNumber>2</motorNumber>
            <rotorDragCoefficient>8.06428e-05</rotorDragCoefficient>
            <rollingMomentCoefficient>1e-06</rollingMomentCoefficient>
            <motorSpeedPubTopic>motor_speed/2</motorSpeedPubTopic>
            <rotorVelocitySlowdownSim>10</rotorVelocitySlowdownSim>
        </plugin>
        <plugin name='voliro_left_motor_model' filename='librotors_gazebo_motor_model.so'>
            <robotNamespace/>
            <jointName>rotor_1_joint</jointName>
            <linkName>rotor_1</linkName>
            <turningDirection>ccw</turningDirection>
            <timeConstantUp>0.0125</timeConstantUp>
            <timeConstantDown>0.025</timeConstantDown>
            <maxRotVelocity>838</maxRotVelocity>
            <motorConstant>1.0258296e-05</motorConstant>
            <momentConstant>0.016</momentConstant>
            <commandSubTopic>/gazebo/command/motor_speed</commandSubTopic>
            <motorNumber>1</motorNumber>
            <rotorDragCoefficient>8.06428e-05</rotorDragCoefficient>
            <rollingMomentCoefficient>1e-06</rollingMomentCoefficient>
            <motorSpeedPubTopic>/motor_speed/1</motorSpeedPubTopic>
            <rotorVelocitySlowdownSim>10</rotorVelocitySlowdownSim>
        </plugin>
        <plugin name='voliro_back_left_motor_model' filename='librotors_gazebo_motor_model.so'>
            <robotNamespace/>
            <jointName>rotor_2_joint</jointName>
            <linkName>rotor_2</linkName>
            <turningDirection>cw</turningDirection>
            <timeConstantUp>0.0125</timeConstantUp>
            <timeConstantDown>0.025</timeConstantDown>
            <maxRotVelocity>838</maxRotVelocity>
            <motorConstant>1.0258296e-05</motorConstant>
            <momentConstant>0.016</momentConstant>
            <commandSubTopic>/gazebo/command/motor_speed</commandSubTopic>
            <motorNumber>5</motorNumber>
            <rotorDragCoefficient>8.06428e-05</rotorDragCoefficient>
            <rollingMomentCoefficient>1e-06</rollingMomentCoefficient>
            <motorSpeedPubTopic>/motor_speed/5</motorSpeedPubTopic>
            <rotorVelocitySlowdownSim>10</rotorVelocitySlowdownSim>
        </plugin>
        <plugin name='voliro_back_right_motor_model' filename='librotors_gazebo_motor_model.so'>
            <robotNamespace/>
            <jointName>rotor_3_joint</jointName>
            <linkName>rotor_3</linkName>
            <turningDirection>ccw</turningDirection>
            <timeConstantUp>0.0125</timeConstantUp>
            <timeConstantDown>0.025</timeConstantDown>
            <maxRotVelocity>838</maxRotVelocity>
            <motorConstant>1.0258296e-05</motorConstant>
            <momentConstant>0.016</momentConstant>
            <commandSubTopic>/gazebo/command/motor_speed</commandSubTopic>
            <motorNumber>3</motorNumber>
            <rotorDragCoefficient>8.06428e-05</rotorDragCoefficient>
            <rollingMomentCoefficient>1e-06</rollingMomentCoefficient>
            <motorSpeedPubTopic>/motor_speed/3</motorSpeedPubTopic>
            <rotorVelocitySlowdownSim>10</rotorVelocitySlowdownSim>
        </plugin>
        <plugin name='voliro_right_motor_model' filename='librotors_gazebo_motor_model.so'>
            <robotNamespace/>
            <jointName>rotor_4_joint</jointName>
            <linkName>rotor_4</linkName>
            <turningDirection>cw</turningDirection>
            <timeConstantUp>0.0125</timeConstantUp>
            <timeConstantDown>0.025</timeConstantDown>
            <maxRotVelocity>838</maxRotVelocity>
            <motorConstant>1.0258296e-05</motorConstant>
            <momentConstant>0.016</momentConstant>
            <commandSubTopic>/gazebo/command/motor_speed</commandSubTopic>
            <motorNumber>0</motorNumber>
            <rotorDragCoefficient>8.06428e-05</rotorDragCoefficient>
            <rollingMomentCoefficient>1e-06</rollingMomentCoefficient>
            <motorSpeedPubTopic>/motor_speed/0</motorSpeedPubTopic>
            <rotorVelocitySlowdownSim>10</rotorVelocitySlowdownSim>
        </plugin>
        <plugin name='voliro_front_right_motor_model' filename='librotors_gazebo_motor_model.so'>
            <robotNamespace/>
            <jointName>rotor_5_joint</jointName>
            <linkName>rotor_5</linkName>
            <turningDirection>ccw</turningDirection>
            <timeConstantUp>0.0125</timeConstantUp>
            <timeConstantDown>0.025</timeConstantDown>
            <maxRotVelocity>838</maxRotVelocity>
            <motorConstant>1.0258296e-05</motorConstant>
            <momentConstant>0.016</momentConstant>
            <commandSubTopic>/gazebo/command/motor_speed</commandSubTopic>
            <motorNumber>4</motorNumber>
            <rotorDragCoefficient>8.06428e-05</rotorDragCoefficient>
            <rollingMomentCoefficient>1e-06</rollingMomentCoefficient>
            <motorSpeedPubTopic>/motor_speed/4</motorSpeedPubTopic>
            <rotorVelocitySlowdownSim>10</rotorVelocitySlowdownSim>
        </plugin>
        <plugin name='mavlink_interface' filename='librotors_gazebo_mavlink_interface.so'>
            <robotNamespace/>
            <imuSubTopic>/imu</imuSubTopic>
            <mavlink_addr>INADDR_ANY</mavlink_addr>
            <mavlink_udp_port>14560</mavlink_udp_port>
            <motorSpeedCommandPubTopic>/gazebo/command/motor_speed</motorSpeedCommandPubTopic>
            <control_channels>
                <channel name='rotor0'>
                    <input_index>0</input_index>
                    <input_offset>0</input_offset>
                    <input_scaling>1000</input_scaling>
                    <zero_position_disarmed>0</zero_position_disarmed>
                    <zero_position_armed>100</zero_position_armed>
                    <joint_control_type>velocity</joint_control_type>
                    <joint_name>rotor_4_joint</joint_name>
                </channel>
                <channel name='rotor1'>
                    <input_index>1</input_index>
                    <input_offset>0</input_offset>
                    <input_scaling>1000</input_scaling>
                    <zero_position_disarmed>0</zero_position_disarmed>
                    <zero_position_armed>100</zero_position_armed>
                    <joint_control_type>velocity</joint_control_type>
                    <joint_name>rotor_1_joint</joint_name>
                </channel>
                <channel name='rotor2'>
                    <input_index>2</input_index>
                    <input_offset>0</input_offset>
                    <input_scaling>1000</input_scaling>
                    <zero_position_disarmed>0</zero_position_disarmed>
                    <zero_position_armed>100</zero_position_armed>
                    <joint_control_type>velocity</joint_control_type>
                    <joint_name>rotor_0_joint</joint_name>
                </channel>
                <channel name='rotor3'>
                    <input_index>3</input_index>
                    <input_offset>0</input_offset>
                    <input_scaling>1000</input_scaling>
                    <zero_position_disarmed>0</zero_position_disarmed>
                    <zero_position_armed>100</zero_position_armed>
                    <joint_control_type>velocity</joint_control_type>
                    <joint_name>rotor_3_joint</joint_name>
                </channel>
                <channel name='rotor4'>
                    <input_index>4</input_index>
                    <input_offset>0</input_offset>
                    <input_scaling>1000</input_scaling>
                    <zero_position_disarmed>0</zero_position_disarmed>
                    <zero_position_armed>100</zero_position_armed>
                    <joint_control_type>velocity</joint_control_type>
                    <joint_name>rotor_5_joint</joint_name>
                </channel>
                <channel name='rotor5'>
                    <input_index>5</input_index>
                    <input_offset>0</input_offset>
                    <input_scaling>1000</input_scaling>
                    <zero_position_disarmed>0</zero_position_disarmed>
                    <zero_position_armed>100</zero_position_armed>
                    <joint_control_type>velocity</joint_control_type>
                    <joint_name>rotor_2_joint</joint_name>
                </channel>
            </control_channels>
        </plugin>
        <plugin name='rotors_gazebo_imu_plugin' filename='librotors_gazebo_imu_plugin.so'>
            <robotNamespace/>
            <linkName>/imu_link</linkName>
            <imuTopic>/imu</imuTopic>
            <gyroscopeNoiseDensity>0.0003394</gyroscopeNoiseDensity>
            <gyroscopeRandomWalk>3.8785e-05</gyroscopeRandomWalk>
            <gyroscopeBiasCorrelationTime>1000.0</gyroscopeBiasCorrelationTime>
            <gyroscopeTurnOnBiasSigma>0.0087</gyroscopeTurnOnBiasSigma>
            <accelerometerNoiseDensity>0.004</accelerometerNoiseDensity>
            <accelerometerRandomWalk>0.006</accelerometerRandomWalk>
            <accelerometerBiasCorrelationTime>300.0</accelerometerBiasCorrelationTime>
            <accelerometerTurnOnBiasSigma>0.196</accelerometerTurnOnBiasSigma>
        </plugin>
        <plugin name='gazebo_ros_control' filename='libgazebo_ros_control.so'>
            <robotNamespace>voliro</robotNamespace>
            <robotParam>robot_description</robotParam>
        </plugin>
    </model>
</sdf>
